Workbook

Sheet Sources & Disclaimers
A1: Sources & Disclaimers — Please Read First
A2: This workbook is for research and discussion only. All franchise values are outside estimates, not audited or official figures. Last updated October 6, 2026.
A4: SOURCES BY TAB
A5: NBA Valuations | B5: Forbes annual NBA team valuations (articles and team pages on forbes.com). Official Forbes figures, but Forbes rounds most values to the nearest $25–100M. Row 4 shows which Forbes list and which season's finances each year uses (lists were published in February through Feb 2021, then in October from Oct 2021). The research notes and the sales table below the values cite their own sources.
A6: Revenue | B6: Forbes estimated team revenue ($M), net of revenue sharing and arena debt service, from the same Forbes list as each valuation year. Older years come from Forbes team-page history; 2026 from the Oct 2025 list article.
A7: Operating Income | B7: Forbes estimated operating income / EBITDA ($M) from the same lists. 2025 and 2026 come from the Oct 2024 and Oct 2025 list articles; six cells differ by $1M from the Forbes team page (noted in those cells).
A8: Market Size | B8: Two tables. (1) Metro population, July 1 2017–2025: Census Bureau Vintage 2020 (2017–2019) and Vintage 2025 (2020–2025) MSA estimates; Statistics Canada Table 17-10-0148-01 for Toronto (all uploaded files). There is a boundary break between 2019 and 2020. Column L 'Fixed MSA population' (July 1 2020) is what the Panel uses for every season. (2) Nielsen DMA rank: 2023–24 and 2024–25 only (third-party repost of Nielsen's list); other seasons n/a.
A9: Arena | B9: Season-by-season home arena (same alignment as the Panel): arena name, year opened, team owns arena (Y/N). Current arenas from Forbes team pages; former arenas (Sleep Train Arena, The Palace of Auburn Hills, Bradley Center, Oracle Arena, Staples Center) and ownership changes (Blazers' Moda Center sold to the City of Portland Aug 2024) from news and reference sources in each cell note.
A10: Panel | B10: Long-format dataset (one row per team per season), all formulas pulling from the other tabs. A Forbes value labeled year Y is paired with performance and arena from the season ending in year Y−1. msa_pop is fixed (July 1 2020). covid_finances = 1 flags seasons 2021–2022, whose revenue and operating income reflect COVID-affected 2019–20 and 2020–21 finances.
A11: Sportico & CNBC | B11: Sportico 2025 values (via HoopsRumors, a secondary site) and CNBC February 2026 values (7 teams from CNBC directly, 9 via NBC Sports Bay Area). 14 teams have no CNBC value available.
A12: Salary Cap | B12: Cap and tax lines: official NBA announcements. Payrolls 2017–2022 (seasons 2016–17 to 2021–22): Spotrac NBA Team Tax Tracker 'Salaries' (tax payroll), from user screenshots — each value checked against Spotrac's tax line (Salaries + Space). Payrolls 2023–2026 and tax bills: Sports Business Classroom, HoopsRumors, HoopsHype and Forbes — secondary sources. The two payroll sources may differ slightly in definition.
A13: Team Performance | B13: Win-loss records and playoff results from ChampsOrChumps.us (a secondary site). Champions were spot-checked.
A14: Cell notes | B14: Most data cells carry a note naming the exact source page. Hover over a cell (or right-click > Show Note) to see it.
A15: WHAT COULD BE MISLEADING
A16: Valuations are estimates | B16: Forbes, Sportico and CNBC use different methods and can differ by $1B+ for the same team. Actual sale prices often differ from all three.
A17: Year labels | B17: Each valuation year is labeled by the NBA season it describes (e.g., the October 2025 Forbes list is shown as 2026), not the date published.
A18: League-wide growth | B18: Nearly every team's value roughly quadrupled from 2017 to 2026, mostly from league TV deals. Compare teams against the league average, not in absolute terms.
A19: Correlation ≠ cause | B19: The tax-vs-value and winning-vs-value comparisons show patterns only. They do not prove that spending or winning caused a value change.
A20: Shortened seasons | B20: 2019-20 and 2020-21 were shortened (COVID), so use win % rather than raw wins. 2020-21 tax bills were reduced by the league.
A21: Estimated tax figures | B21: Some 2017–2021 tax bills are rounded or pre-final estimates; the 2021 Utah Jazz amount is unknown.
A22: Typed write-ups | B22: The explanation paragraphs on each tab contain typed numbers. They will NOT update if the data changes; the tables and formulas will.
A23: Gaps | B23: Cells marked n/a mean no reliable source was found. They are not zero.
A24: Oct 2023 re-valuation | B24: The Oct 2023 Forbes list (2024 column) compressed values: small-market teams jumped 60–75% while big-market teams rose about 8%, so small teams caught up. This affects every growth comparison in the workbook (source: Front Office Sports, see note on NBA Valuations!I3).
A26: TO FIND
A27: Metro population (Census) | B27: Market Size K5:K34 and K32 — July 1 2026 metro population (U.S. Census and StatCan have not published 2026 yet; expected ~early 2027). 2017–2019 now filled from the uploaded Census Vintage 2020 file (older boundaries — see series-break note on each cell; biggest breaks: New Orleans −21%, Cleveland +7%, New York +5%, Phoenix −4%).
A28: Toronto population (StatCan) | B28: (Merged into the item above — Toronto 2017–2025 is filled; only 2026 is missing.)
A29: DMA rank (Nielsen) | B29: Market Size B38:H67 and K38:K67 — Nielsen DMA ranks for the 2016–17 to 2022–23 and 2025–26 TV seasons. 2024–25 and 2023–24 are filled from the uploaded National Media Spots repost (third-party). A 2025–26 list is reposted at https://methodshop.com/nielsen-dma-rankings-full-list/ ; older seasons: search 'Local Television Market Universe Estimates' + season. Toronto stays n/a (Numeris, not Nielsen).
A30: Team payroll 2017–2022 | B30: DONE — Salary Cap B10:G39 (2016–17 to 2021–22) and the 2015–16 block at Salary Cap A141:C172 filled from Spotrac tax-tracker screenshots.
A31: Bucks control sale | B31: No Milwaukee Bucks control sale since 2023 was found. The 2023 sale of Marc Lasry's 25% stake (minority) is in the sales table and labeled Minority.
A32: 2015–16 season data | B32: DONE — 2015–16 wins, losses and playoff results added at Team Performance A239:E270 (Basketball-Reference screenshots) and linked into the Panel's season-2017 rows.
A33: Utah 2020–21 tax bill | B33: Salary Cap F137 — Utah 2020–21 tax: Spotrac ESTIMATE ($5,509,202) entered at user's request and highlighted yellow; the actual reported payment is still unknown. Forbes history: https://www.forbes.com/sites/markdeeks/2022/07/01/a-complete-history-of-nba-luxury-tax-payments-20012022/
A34: Older arena ownership (secondary) | B34: Arena tab table (c): two ownership flags rest on secondary sources and should be confirmed with a primary one — Kings 2017 Sleep Train Arena = Y (RetroSeasons) and Bucks 2017–2019 Bradley Center = N (Wikipedia). Also, ownership for arenas that did not change is taken from Forbes' Oct 2025 team pages and assumed unchanged back to 2015–16 (no change found in research).

Sheet NBA Valuations
A1: NBA Franchise Valuations ($ millions)
A2: Forbes estimates, $ millions. Year = NBA season the list covers (e.g., 2026 = 2025–26 season, Forbes list published Oct 2025). Row 4 shows which list and which season's finances each year uses. n/a = not found. Hover over a value to see its source.
A3: NBA Team | B3: 2017 | C3: 2018 | D3: 2019 | E3: 2020 | F3: 2021 | G3: 2022 | H3: 2023 | I3: 2024 | J3: 2025 | K3: 2026
A4: Financial season used | B4: Feb 2017 list; 2015–16 finances | C4: Feb 2018 list; 2016–17 finances | D4: Feb 2019 list; 2017–18 finances | E4: Feb 2020 list; 2018–19 finances | F4: Feb 2021 list; 2019–20 finances | G4: Oct 2021 list; 2020–21 finances | H4: Oct 2022 list; 2021–22 finances | I4: Oct 2023 list; 2022–23 finances | J4: Oct 2024 list; 2023–24 finances | K4: Oct 2025 list; 2024–25 finances
A5: Atlanta Hawks | B5: 885 | C5: 1200 | D5: 1300 | E5: 1500 | F5: 1520 | G5: 1680 | H5: 1975 | I5: 3320 | J5: 3800 | K5: 5000
A6: Boston Celtics | B6: 2200 | C6: 2500 | D6: 2800 | E6: 3100 | F6: 3200 | G6: 3550 | H6: 4000 | I6: 4700 | J6: 6000 | K6: 6700
A7: Brooklyn Nets | B7: 1800 | C7: 2300 | D7: 2400 | E7: 2500 | F7: 2650 | G7: 3200 | H7: 3500 | I7: 3850 | J7: 4800 | K7: 5600
A8: Charlotte Hornets | B8: 780 | C8: 1100 | D8: 1300 | E8: 1500 | F8: 1500 | G8: 1575 | H8: 1700 | I8: 3000 | J8: 3300 | K8: 3800
A9: Chicago Bulls | B9: 2500 | C9: 2600 | D9: 2900 | E9: 3200 | F9: 3300 | G9: 3650 | H9: 4100 | I9: 4600 | J9: 5000 | K9: 6000
A10: Cleveland Cavaliers | B10: 1200 | C10: 1300 | D10: 1300 | E10: 1500 | F10: 1560 | G10: 1650 | H10: 2050 | I10: 3350 | J10: 3950 | K10: 4800
A11: Dallas Mavericks | B11: 1500 | C11: 1900 | D11: 2300 | E11: 2400 | F11: 2450 | G11: 2700 | H11: 3300 | I11: 4500 | J11: 4700 | K11: 5100
A12: Denver Nuggets | B12: 890 | C12: 1100 | D12: 1400 | E12: 1600 | F12: 1650 | G12: 1730 | H12: 1930 | I12: 3370 | J12: 3900 | K12: 4600
A13: Detroit Pistons | B13: 900 | C13: 1100 | D13: 1300 | E13: 1500 | F13: 1450 | G13: 1580 | H13: 1900 | I13: 3070 | J13: 3400 | K13: 3650
A14: Golden State Warriors | B14: 2600 | C14: 3100 | D14: 3500 | E14: 4300 | F14: 4700 | G14: 5600 | H14: 7000 | I14: 7700 | J14: 8800 | K14: 11000
A15: Houston Rockets | B15: 1700 | C15: 2200 | D15: 2300 | E15: 2500 | F15: 2500 | G15: 2750 | H15: 3200 | I15: 4400 | J15: 4900 | K15: 5900
A16: Indiana Pacers | B16: 880 | C16: 1200 | D16: 1400 | E16: 1500 | F16: 1550 | G16: 1670 | H16: 1800 | I16: 2900 | J16: 3600 | K16: 4200
... A34: Washington Wizards | B34: 1000 | C34: 1400 | D34: 1600 | E34: 1800 | F34: 1800 | G34: 1930 | H34: 2500 | I34: 3500 | J34: 4100 | K34: 4700
A37: Research Findings & Notes
A38: Topic | B38: Finding | H38: Source
A39: How teams are valued (methodology) | B39: Forbes values each team as an enterprise value (equity plus net debt), using revenue multiples and each team's current arena deal. Values include arena economics (including non-NBA event revenue that goes to the owner) but not the value of the arena real estate. Forbes revenue and operating income are net of revenue sharing and arena debt service. | H39: Forbes, Most Valuable NBA Teams 2024 (methodology), https://www.forbes.com/sites/justinteitelbaum/2024/10/24/the-most-valuable-nba-teams-2024/
A40: Key value drivers | B40: National media rights (league-wide TV and streaming packages, shared equally by all teams); arena economics (ticket sales, premium seating and suites, and control of non-basketball event income at the arena); local market and sponsorships (local media and streaming rights, corporate sponsorships, global brand strength); and profitability and debt (operating income/EBITDA, and net debt relative to team value).
A41: Media / TV deals | B41: The NBA sells exclusive rights to broadcast and stream games to media companies and shares the money between the league and its teams. The current national package is an 11-year agreement running from 2025–26 through 2035–36, reported at about $76 billion, split among three partners: Walt Disney (ABC/ESPN) – regular-season games, the NBA Finals and conference finals; NBCUniversal (NBC/Peacock) – regular-season games, Opening Night and Sunday/Tuesday games; and Amazon Prime Video – Thursday/Friday games, the NBA Cup (in-season tournament) and Play-In games. National media deals (league level): the NBA negotiates national packages collectively as a single entity, and the money goes into a central pool that is shared equally among all 30 teams through basketball-related income (BRI). Local media deals (team level): each team negotiates its own local TV, radio and regional sports network or streaming rights in its home market. That revenue stays mainly with the team, which creates large differences between big markets (e.g., Los Angeles, New York) and small markets. | H41: Deal size per Forbes, Most Valuable NBA Teams 2024, https://www.forbes.com/sites/justinteitelbaum/2024/10/24/the-most-valuable-nba-teams-2024/
A42: Major sales & ownership changes | B42: See the transactions table below (rows 49–57). Prices are as reported when each deal was agreed or approved, and are valuations for 100% of the team. | H42: See Source column in the table
A43: Relocations & name changes | B43: Major NBA relocations and name changes (original franchise → history → current team): Minneapolis Lakers (1947) → moved in 1960, kept the name → Los Angeles Lakers Tri-Cities Blackhawks (1946) → Milwaukee (1951), St. Louis (1955), Atlanta (1968) → Atlanta Hawks Rochester Royals (1948) → Cincinnati (1957), Kansas City/Omaha (1972), Kansas City (1975) → Sacramento Kings New Orleans Jazz (1974) → relocated in 1979, kept the name → Utah Jazz Buffalo Braves (1970) → San Diego (1978), Los Angeles (1984) → LA Clippers Washington Bullets (1973) → renamed in 1997 → Washington Wizards Vancouver Grizzlies (1995) → relocated before the 2001–02 season → Memphis Grizzlies Charlotte Hornets (1988) → moved in 2002, renamed Pelicans in 2013 → New Orleans Pelicans Seattle SuperSonics (1967) → moved in 2008; the SuperSonics name stayed in Seattle → Oklahoma City Thunder New Jersey Nets (1976) → moved to Brooklyn in 2012 → Brooklyn Nets Charlotte Bobcats (2004) → renamed Hornets in 2014 → Charlotte Hornets
A44: Trends over time | B44: Every team's Forbes value rose between the Feb 2017 and Oct 2025 lists (see the table above). The largest one-year jump came in the Oct 2023 list (2024 column): Forbes' average value rose about 35%, which Forbes attributed to the expected new national media deal and the Suns and Hornets sales (see the note on the 2024 header). The Oct 2023 list compressed values (small teams caught up), which affects every growth comparison. Because national media money is split equally, a bigger national deal raises every team's baseline value. Teams that control their arena can also capture non-NBA event revenue (see the Arena tab). | H44: Front Office Sports (Oct 2023 list), https://frontofficesports.com/article/most-valuable-nba-franchises-2023-golden-state-warriors/
A45: Salary cap and value | B45: The salary cap is set from projected basketball-related income (BRI), so it rises and falls with league revenue. It is a soft cap: teams can go over it using exceptions (such as Bird rights). Teams over the luxury tax line at the end of the season pay a tax that increases the further they are over, with higher rates for repeat taxpayers; tax money is distributed to non-taxpaying teams. The 2023 labor deal added a first and second 'apron' above the tax line that restrict trades and roster-building tools. For 2026–27 the cap is $164.961M and the tax line is $200.428M (see the Salary Cap tab). | H45: Cap and tax figures: official NBA announcements (Salary Cap tab)
A48: Major Sales & Ownership Changes (2023 onward)
A49: Team | B49: Date | C49: Price/Valuation ($M) | D49: Seller | E49: Buyer | F49: Control or Minority | G49: Source
A50: Phoenix Suns | B50: Feb 6, 2023 (approved; agreed Dec 20, 2022) | C50: 4000 | D50: Robert Sarver (plus part of some minority stakes) | E50: Mat Ishbia and Justin Ishbia | F50: Control | G50: Boston Globe / Associated Press, https://www.bostonglobe.com/2023/02/06/sports/nba-approves-sale-phoenix-suns-mercury-mat-ishbia-4-billion/
A51: Milwaukee Bucks | B51: Feb 27, 2023 (agreement reported) | C51: 3500 | D51: Marc Lasry (25% stake) | E51: Jimmy and Dee Haslam | F51: Minority | G51: ESPN, https://www.espn.com/espn/print?id=35746705
A52: Charlotte Hornets | B52: Jul 23, 2023 (approved; agreed Jun 16, 2023) | C52: 3000 | D52: Michael Jordan | E52: Group led by Gabe Plotkin and Rick Schnall | F52: Control | G52: CBS News Chicago / CBS Sports, https://www.cbsnews.com/chicago/news/michael-jordan-sale-charlotte-hornets/
A53: Dallas Mavericks | B53: Dec 27, 2023 (approved) | C53: 3500 | D53: Mark Cuban | E53: Adelson and Dumont families (Las Vegas Sands) | F53: Control | G53: CBS News Texas / Associated Press, https://www.cbsnews.com/texas/news/nba-approves-sale-dallas-mavericks-las-vegas-sands-miriam-adelson/
A54: Los Angeles Lakers | B54: Jun 2025 (agreed) | C54: 10000 | D54: Buss family | E54: Mark Walter | F54: Control | G54: ABC7, https://abc7.com/16783698/
A55: Minnesota Timberwolves | B55: May 14, 2021 (agreed at $1.5B; final NBA approval Jun 2025 after arbitration) | C55: 1500 | D55: Glen Taylor | E55: Group led by Marc Lore and Alex Rodriguez | F55: Control | G55: CBS Sports (2021 agreement), https://www.cbssports.com/nba/news/alex-rodriguezs-ownership-group-reaches-agreement-to-buy-timberwolves-lynx-for-1-5-billion ; ESPN (2025 approval), https://www.espn.com/nba/story/_/id/45577217
A56: Boston Celtics | B56: Aug 13, 2025 (approved; agreed Mar 2025) | C56: 6100 | D56: Grousbeck family-led ownership group | E56: Group led by Bill Chisholm | F56: Control | G56: ESPN, https://www.espn.com/nba/story/_/id/45969002/nba-approves-celtics-sale-record-61-billion-valuation
A57: Portland Trail Blazers | B57: Mar 30, 2026 (approved; agreed Aug 2025) | C57: 4250 | D57: Estate of Paul Allen | E57: Group led by Tom Dundon | F57: Control | G57: Reuters (via WTVB), https://wtvbam.com/2026/03/30/nba-approves-sale-of-trail-blazers-to-tom-dundon-led-group/

Sheet Revenue
A1: NBA Team Revenue ($ millions)
A2: Forbes estimated team revenue, $ millions, from the same Forbes list as each valuation year (row 4). Net of revenue sharing and arena debt service. Hover over a value to see its source.
A3: NBA Team | B3: 2017 | C3: 2018 | D3: 2019 | E3: 2020 | F3: 2021 | G3: 2022 | H3: 2023 | I3: 2024 | J3: 2025 | K3: 2026
A4: Financial season used | B4: Feb 2017 list; 2015–16 finances | C4: Feb 2018 list; 2016–17 finances | D4: Feb 2019 list; 2017–18 finances | E4: Feb 2020 list; 2018–19 finances | F4: Feb 2021 list; 2019–20 finances | G4: Oct 2021 list; 2020–21 finances | H4: Oct 2022 list; 2021–22 finances | I4: Oct 2023 list; 2022–23 finances | J4: Oct 2024 list; 2023–24 finances | K4: Oct 2025 list; 2024–25 finances
A5: Atlanta Hawks | B5: 169 | C5: 209 | D5: 215 | E5: 251 | F5: 222 | G5: 199 | H5: 282 | I5: 326 | J5: 353 | K5: 477
A6: Boston Celtics | B6: 200 | C6: 257 | D6: 287 | E6: 304 | F6: 274 | G6: 211 | H6: 361 | I6: 443 | J6: 457 | K6: 458
A7: Brooklyn Nets | B7: 223 | C7: 273 | D7: 290 | E7: 304 | F7: 280 | G7: 212 | H7: 405 | I7: 367 | J7: 381 | K7: 402
A8: Charlotte Hornets | B8: 158 | C8: 202 | D8: 213 | E8: 240 | F8: 215 | G8: 183 | H8: 269 | I8: 269 | J8: 308 | K8: 328
A9: Chicago Bulls | B9: 232 | C9: 281 | D9: 287 | E9: 301 | F9: 300 | G9: 213 | H9: 352 | I9: 372 | J9: 414 | K9: 434
A10: Cleveland Cavaliers | B10: 233 | C10: 280 | D10: 302 | E10: 300 | F10: 269 | G10: 211 | H10: 325 | I10: 348 | J10: 391 | K10: 440
A11: Dallas Mavericks | B11: 194 | C11: 233 | D11: 287 | E11: 307 | F11: 295 | G11: 231 | H11: 364 | I11: 429 | J11: 437 | K11: 407
A12: Denver Nuggets | B12: 157 | C12: 202 | D12: 222 | E12: 252 | F12: 218 | G12: 185 | H12: 273 | I12: 348 | J12: 356 | K12: 364
A13: Detroit Pistons | B13: 172 | C13: 221 | D13: 235 | E13: 255 | F13: 227 | G13: 192 | H13: 278 | I13: 274 | J13: 305 | K13: 321
A14: Golden State Warriors | B14: 305 | C14: 359 | D14: 401 | E14: 440 | F14: 474 | G14: 258 | H14: 765 | I14: 765 | J14: 800 | K14: 880
A15: Houston Rockets | B15: 244 | C15: 296 | D15: 326 | E15: 348 | F15: 308 | G15: 223 | H15: 350 | I15: 381 | J15: 416 | K15: 467
A16: Indiana Pacers | B16: 157 | C16: 205 | D16: 222 | E16: 243 | F16: 217 | G16: 179 | H16: 264 | I16: 263 | J16: 320 | K16: 342
... A34: Washington Wizards | B34: 155 | C34: 222 | D34: 255 | E34: 269 | F34: 231 | G34: 213 | H34: 291 | I34: 323 | J34: 362 | K34: 389

Sheet Operating Income
A1: NBA Team Operating Income ($ millions)
A2: Forbes estimated operating income (EBITDA), $ millions, from the same Forbes list as each valuation year (row 4). Negative = operating loss, shown in parentheses. Hover over a value to see its source.
A3: NBA Team | B3: 2017 | C3: 2018 | D3: 2019 | E3: 2020 | F3: 2021 | G3: 2022 | H3: 2023 | I3: 2024 | J3: 2025 | K3: 2026
A4: Financial season used | B4: Feb 2017 list; 2015–16 finances | C4: Feb 2018 list; 2016–17 finances | D4: Feb 2019 list; 2017–18 finances | E4: Feb 2020 list; 2018–19 finances | F4: Feb 2021 list; 2019–20 finances | G4: Oct 2021 list; 2020–21 finances | H4: Oct 2022 list; 2021–22 finances | I4: Oct 2023 list; 2022–23 finances | J4: Oct 2024 list; 2023–24 finances | K4: Oct 2025 list; 2024–25 finances
A5: Atlanta Hawks | B5: 19.8 | C5: 22 | D5: 42 | E5: 78 | F5: 36 | G5: 37 | H5: 84 | I5: 85 | J5: 94 | K5: 203
A6: Boston Celtics | B6: 60.1 | C6: 85 | D6: 100 | E6: 88 | F6: 86 | G6: 46 | H6: 137 | I6: 88 | J6: 121 | K6: 116
A7: Brooklyn Nets | B7: 15.7 | C7: 52 | D7: 53 | E7: 42 | F7: 44 | G7: -80 | H7: -34 | I7: -5.4 | J7: 43 | K7: 50
A8: Charlotte Hornets | B8: 9.4 | C8: 21 | D8: 22 | E8: 39 | F8: 36 | G8: 34 | H8: 94 | I8: 35 | J8: 84 | K8: 82
A9: Chicago Bulls | B9: 45.5 | C9: 95 | D9: 114 | E9: 103 | F9: 115 | G9: 39 | H9: 135 | I9: 115 | J9: 140 | K9: 160
A10: Cleveland Cavaliers | B10: -40.2 | C10: -6.2 | D10: -13 | E10: 39 | F10: 46 | G10: 11 | H10: 74 | I10: 78 | J10: 97 | K10: 127
A11: Dallas Mavericks | B11: 40.3 | C11: 21 | D11: 99 | E11: 105 | F11: 84 | G11: 55 | H11: 143 | I11: 83 | J11: 158 | K11: 87
A12: Denver Nuggets | B12: 21.2 | C12: 49 | D12: 47 | E12: 52 | F12: 27 | G12: 15 | H12: 67 | I12: 71 | J12: 57 | K12: 67
A13: Detroit Pistons | B13: 21.8 | C13: 22 | D13: 52 | E13: 52 | F13: 45 | G13: 43 | H13: 92 | I13: 83 | J13: 89 | K13: 106
A14: Golden State Warriors | B14: 74.2 | C14: 120 | D14: 103 | E14: 109 | F14: 200 | G14: -44 | H14: 206 | I14: 79 | J14: 142 | K14: 409
A15: Houston Rockets | B15: 62.7 | C15: 95 | D15: 103 | E15: 110 | F15: 94 | G15: 33 | H15: 113 | I15: 125 | J15: 160 | K15: 191
A16: Indiana Pacers | B16: 23.9 | C16: 29 | D16: 50 | E16: 55 | F16: 39 | G16: 4.1 | H16: 65 | I16: 68 | J16: 94 | K16: 89
... A34: Washington Wizards | B34: 6.6 | C34: 21 | D34: 34 | E34: 55 | F34: 39 | G34: 15 | H34: 90 | I34: 85 | J34: 118 | K34: 135

Sheet Market Size
A1: NBA Market Size
A2: Two tables: (1) metro population, July 1 estimate for each year, plus column L 'Fixed MSA population' (July 1 2020) used by the Panel; (2) Nielsen DMA (TV market) rank for the TV season ending that year (e.g., 2026 = 2025–26 season). n/a = not found yet — see the To Find list on the Sources & Disclaimers tab.
A3: Metro Population (MSA) – Census | B3: 2017 | C3: 2018 | D3: 2019 | E3: 2020 | F3: 2021 | G3: 2022 | H3: 2023 | I3: 2024 | J3: 2025 | K3: 2026 | L3: Fixed MSA population
A4: Estimate date | B4: Jul 1 2017 | C4: Jul 1 2018 | D4: Jul 1 2019 | E4: Jul 1 2020 | F4: Jul 1 2021 | G4: Jul 1 2022 | H4: Jul 1 2023 | I4: Jul 1 2024 | J4: Jul 1 2025 | K4: Jul 1 2026 | L4: Jul 1 2020
A5: Atlanta Hawks | B5: 5876763 | C5: 5951394 | D5: 6027231 | E5: 6120770 | F5: 6160335 | G5: 6250876 | H5: 6333350 | I5: 6420229 | J5: 6482182 | K5: n/a | L5: =E5 -> 6120770
A6: Boston Celtics | B6: 4845221 | C6: 4862290 | D6: 4876271 | E6: 4921409 | F6: 4907671 | G6: 4933469 | H6: 4970657 | I6: 5022230 | J6: 5034221 | K6: n/a | L6: =E6 -> 4921409
A7: Brooklyn Nets | B7: 19325115 | C7: 19289420 | D7: 19232494 | E7: 19999993 | F7: 19704474 | G7: 19629390 | H7: 19788976 | I7: 20080087 | J7: 20112448 | K7: n/a | L7: =E7 -> 19999993
A8: Charlotte Hornets | B8: 2552701 | C8: 2596204 | D8: 2640117 | E8: 2668342 | F8: 2706093 | G8: 2758749 | H8: 2818271 | I8: 2884708 | J8: 2938830 | K8: n/a | L8: =E8 -> 2668342
A9: Chicago Bulls | B9: 9513947 | C9: 9485403 | D9: 9454282 | E9: 9435971 | F9: 9365495 | G9: 9303151 | H9: 9335921 | I9: 9411198 | J9: 9434123 | K9: n/a | L9: =E9 -> 9435971
A10: Cleveland Cavaliers | B10: 2057650 | C10: 2053841 | D10: 2049028 | E10: 2184166 | F10: 2169628 | G10: 2160973 | H10: 2161313 | I10: 2163236 | J10: 2165775 | K10: n/a | L10: =E10 -> 2184166
A11: Dallas Mavericks | B11: 7337707 | C11: 7457586 | D11: 7574390 | E11: 7667416 | F11: 7777844 | G11: 7972652 | H11: 8164140 | I11: 8353600 | J11: 8477157 | K11: n/a | L11: =E11 -> 7667416
A12: Denver Nuggets | B12: 2893661 | C12: 2933991 | D12: 2964811 | E12: 2970099 | F12: 2978802 | G12: 2994295 | H12: 3031278 | I12: 3081092 | J12: 3092037 | K12: n/a | L12: =E12 -> 2970099
A13: Detroit Pistons | B13: 4322490 | C13: 4323861 | D13: 4319413 | E13: 4385353 | F13: 4370695 | G13: 4354135 | H13: 4356818 | I13: 4377045 | J13: 4390913 | K13: n/a | L13: =E13 -> 4385353
A14: Golden State Warriors | B14: 4711551 | C14: 4725613 | D14: 4724016 | E14: 4745853 | F14: 4623626 | G14: 4595850 | H14: 4601326 | I14: 4623434 | J14: 4630041 | K14: n/a | L14: =E14 -> 4745853
A15: Houston Rockets | B15: 6898912 | C15: 6974948 | D15: 7063400 | E15: 7169284 | F15: 7248044 | G15: 7406285 | H15: 7587646 | I15: 7777907 | J15: 7904627 | K15: n/a | L15: =E15 -> 7169284
A16: Indiana Pacers | B16: 2028973 | C16: 2053475 | D16: 2073336 | E16: 2092783 | F16: 2106709 | G16: 2126489 | H16: 2152012 | I16: 2183424 | J16: 2205695 | K16: n/a | L16: =E16 -> 2092783
... A34: Washington Wizards | B34: 6217791 | C34: 6256312 | D34: 6297454 | E34: 6260638 | F34: 6259621 | G34: 6280312 | H34: 6328730 | I34: 6415518 | J34: 6465724 | K34: n/a | L34: =E34 -> 6260638
A36: DMA Rank – Nielsen | B36: 2017 | C36: 2018 | D36: 2019 | E36: 2020 | F36: 2021 | G36: 2022 | H36: 2023 | I36: 2024 | J36: 2025 | K36: 2026
A37: TV season | B37: 2016–17 | C37: 2017–18 | D37: 2018–19 | E37: 2019–20 | F37: 2020–21 | G37: 2021–22 | H37: 2022–23 | I37: 2023–24 | J37: 2024–25 | K37: 2025–26
A38: Atlanta Hawks | B38: n/a | C38: n/a | D38: n/a | E38: n/a | F38: n/a | G38: n/a | H38: n/a | I38: 6 | J38: 7 | K38: n/a
A39: Boston Celtics | B39: n/a | C39: n/a | D39: n/a | E39: n/a | F39: n/a | G39: n/a | H39: n/a | I39: 9 | J39: 9 | K39: n/a
A40: Brooklyn Nets | B40: n/a | C40: n/a | D40: n/a | E40: n/a | F40: n/a | G40: n/a | H40: n/a | I40: 1 | J40: 1 | K40: n/a
A41: Charlotte Hornets | B41: n/a | C41: n/a | D41: n/a | E41: n/a | F41: n/a | G41: n/a | H41: n/a | I41: 21 | J41: 21 | K41: n/a
A42: Chicago Bulls | B42: n/a | C42: n/a | D42: n/a | E42: n/a | F42: n/a | G42: n/a | H42: n/a | I42: 3 | J42: 3 | K42: n/a
A43: Cleveland Cavaliers | B43: n/a | C43: n/a | D43: n/a | E43: n/a | F43: n/a | G43: n/a | H43: n/a | I43: 19 | J43: 19 | K43: n/a
A44: Dallas Mavericks | B44: n/a | C44: n/a | D44: n/a | E44: n/a | F44: n/a | G44: n/a | H44: n/a | I44: 5 | J44: 4 | K44: n/a
A45: Denver Nuggets | B45: n/a | C45: n/a | D45: n/a | E45: n/a | F45: n/a | G45: n/a | H45: n/a | I45: 16 | J45: 17 | K45: n/a
A46: Detroit Pistons | B46: n/a | C46: n/a | D46: n/a | E46: n/a | F46: n/a | G46: n/a | H46: n/a | I46: 14 | J46: 14 | K46: n/a
A47: Golden State Warriors | B47: n/a | C47: n/a | D47: n/a | E47: n/a | F47: n/a | G47: n/a | H47: n/a | I47: 10 | J47: 10 | K47: n/a
A48: Houston Rockets | B48: n/a | C48: n/a | D48: n/a | E48: n/a | F48: n/a | G48: n/a | H48: n/a | I48: 7 | J48: 6 | K48: n/a
A49: Indiana Pacers | B49: n/a | C49: n/a | D49: n/a | E49: n/a | F49: n/a | G49: n/a | H49: n/a | I49: 25 | J49: 25 | K49: n/a
... A64: San Antonio Spurs | B64: n/a | C64: n/a | D64: n/a | E64: n/a | F64: n/a | G64: n/a | H64: n/a | I64: 31 | J64: 31 | K64: n/a
A65: Toronto Raptors | B65: n/a | C65: n/a | D65: n/a | E65: n/a | F65: n/a | G65: n/a | H65: n/a | I65: n/a | J65: n/a | K65: n/a
A66: Utah Jazz | B66: n/a | C66: n/a | D66: n/a | E66: n/a | F66: n/a | G66: n/a | H66: n/a | I66: 29 | J66: 28 | K66: n/a
A67: Washington Wizards | B67: n/a | C67: n/a | D67: n/a | E67: n/a | F67: n/a | G67: n/a | H67: n/a | I67: 8 | J67: 8 | K67: n/a

Sheet Arena
A1: NBA Team Arenas
A2: Home arena by season, same alignment as the Panel: column Y = the arena used in the season ending Y−1 (e.g., 2026 = 2024–25 season). Three tables: (a) arena name, (b) year that arena opened, (c) team owns arena — Y if the team or its controlling owner/affiliated company owns the building, N if a government body or unrelated company owns it. Arena names are each building's current name. Hover over any cell for its source.
A3: (a) Arena name | B3: 2017 | C3: 2018 | D3: 2019 | E3: 2020 | F3: 2021 | G3: 2022 | H3: 2023 | I3: 2024 | J3: 2025 | K3: 2026
A4: Season played | B4: 2015–16 | C4: 2016–17 | D4: 2017–18 | E4: 2018–19 | F4: 2019–20 | G4: 2020–21 | H4: 2021–22 | I4: 2022–23 | J4: 2023–24 | K4: 2024–25
A5: Atlanta Hawks | B5: State Farm Arena | C5: State Farm Arena | D5: State Farm Arena | E5: State Farm Arena | F5: State Farm Arena | G5: State Farm Arena | H5: State Farm Arena | I5: State Farm Arena | J5: State Farm Arena | K5: State Farm Arena
A6: Boston Celtics | B6: TD Garden | C6: TD Garden | D6: TD Garden | E6: TD Garden | F6: TD Garden | G6: TD Garden | H6: TD Garden | I6: TD Garden | J6: TD Garden | K6: TD Garden
A7: Brooklyn Nets | B7: Barclays Center | C7: Barclays Center | D7: Barclays Center | E7: Barclays Center | F7: Barclays Center | G7: Barclays Center | H7: Barclays Center | I7: Barclays Center | J7: Barclays Center | K7: Barclays Center
A8: Charlotte Hornets | B8: Spectrum Center | C8: Spectrum Center | D8: Spectrum Center | E8: Spectrum Center | F8: Spectrum Center | G8: Spectrum Center | H8: Spectrum Center | I8: Spectrum Center | J8: Spectrum Center | K8: Spectrum Center
A9: Chicago Bulls | B9: United Center | C9: United Center | D9: United Center | E9: United Center | F9: United Center | G9: United Center | H9: United Center | I9: United Center | J9: United Center | K9: United Center
A10: Cleveland Cavaliers | B10: Rocket Arena | C10: Rocket Arena | D10: Rocket Arena | E10: Rocket Arena | F10: Rocket Arena | G10: Rocket Arena | H10: Rocket Arena | I10: Rocket Arena | J10: Rocket Arena | K10: Rocket Arena
A11: Dallas Mavericks | B11: American Airlines Center | C11: American Airlines Center | D11: American Airlines Center | E11: American Airlines Center | F11: American Airlines Center | G11: American Airlines Center | H11: American Airlines Center | I11: American Airlines Center | J11: American Airlines Center | K11: American Airlines Center
A12: Denver Nuggets | B12: Ball Arena | C12: Ball Arena | D12: Ball Arena | E12: Ball Arena | F12: Ball Arena | G12: Ball Arena | H12: Ball Arena | I12: Ball Arena | J12: Ball Arena | K12: Ball Arena
A13: Detroit Pistons | B13: The Palace of Auburn Hills | C13: The Palace of Auburn Hills | D13: Little Caesars Arena | E13: Little Caesars Arena | F13: Little Caesars Arena | G13: Little Caesars Arena | H13: Little Caesars Arena | I13: Little Caesars Arena | J13: Little Caesars Arena | K13: Little Caesars Arena
A14: Golden State Warriors | B14: Oracle Arena | C14: Oracle Arena | D14: Oracle Arena | E14: Oracle Arena | F14: Chase Center | G14: Chase Center | H14: Chase Center | I14: Chase Center | J14: Chase Center | K14: Chase Center
... A37: Season played | B37: 2015–16 | C37: 2016–17 | D37: 2017–18 | E37: 2018–19 | F37: 2019–20 | G37: 2020–21 | H37: 2021–22 | I37: 2022–23 | J37: 2023–24 | K37: 2024–25
A38: Atlanta Hawks | B38: 1999 | C38: 1999 | D38: 1999 | E38: 1999 | F38: 1999 | G38: 1999 | H38: 1999 | I38: 1999 | J38: 1999 | K38: 1999
A39: Boston Celtics | B39: 1995 | C39: 1995 | D39: 1995 | E39: 1995 | F39: 1995 | G39: 1995 | H39: 1995 | I39: 1995 | J39: 1995 | K39: 1995
A40: Brooklyn Nets | B40: 2012 | C40: 2012 | D40: 2012 | E40: 2012 | F40: 2012 | G40: 2012 | H40: 2012 | I40: 2012 | J40: 2012 | K40: 2012
A41: Charlotte Hornets | B41: 2005 | C41: 2005 | D41: 2005 | E41: 2005 | F41: 2005 | G41: 2005 | H41: 2005 | I41: 2005 | J41: 2005 | K41: 2005
A42: Chicago Bulls | B42: 1994 | C42: 1994 | D42: 1994 | E42: 1994 | F42: 1994 | G42: 1994 | H42: 1994 | I42: 1994 | J42: 1994 | K42: 1994
A43: Cleveland Cavaliers | B43: 1994 | C43: 1994 | D43: 1994 | E43: 1994 | F43: 1994 | G43: 1994 | H43: 1994 | I43: 1994 | J43: 1994 | K43: 1994
A44: Dallas Mavericks | B44: 2001 | C44: 2001 | D44: 2001 | E44: 2001 | F44: 2001 | G44: 2001 | H44: 2001 | I44: 2001 | J44: 2001 | K44: 2001
A45: Denver Nuggets | B45: 1999 | C45: 1999 | D45: 1999 | E45: 1999 | F45: 1999 | G45: 1999 | H45: 1999 | I45: 1999 | J45: 1999 | K45: 1999
A46: Detroit Pistons | B46: 1988 | C46: 1988 | D46: 2017 | E46: 2017 | F46: 2017 | G46: 2017 | H46: 2017 | I46: 2017 | J46: 2017 | K46: 2017
A47: Golden State Warriors | B47: 1966 | C47: 1966 | D47: 1966 | E47: 1966 | F47: 2019 | G47: 2019 | H47: 2019 | I47: 2019 | J47: 2019 | K47: 2019
A48: Houston Rockets | B48: 2003 | C48: 2003 | D48: 2003 | E48: 2003 | F48: 2003 | G48: 2003 | H48: 2003 | I48: 2003 | J48: 2003 | K48: 2003
A49: Indiana Pacers | B49: 1999 | C49: 1999 | D49: 1999 | E49: 1999 | F49: 1999 | G49: 1999 | H49: 1999 | I49: 1999 | J49: 1999 | K49: 1999
... A67: Washington Wizards | B67: 1997 | C67: 1997 | D67: 1997 | E67: 1997 | F67: 1997 | G67: 1997 | H67: 1997 | I67: 1997 | J67: 1997 | K67: 1997
A69: (c) Team owns arena | B69: 2017 | C69: 2018 | D69: 2019 | E69: 2020 | F69: 2021 | G69: 2022 | H69: 2023 | I69: 2024 | J69: 2025 | K69: 2026
A70: Season played | B70: 2015–16 | C70: 2016–17 | D70: 2017–18 | E70: 2018–19 | F70: 2019–20 | G70: 2020–21 | H70: 2021–22 | I70: 2022–23 | J70: 2023–24 | K70: 2024–25
A71: Atlanta Hawks | B71: N | C71: N | D71: N | E71: N | F71: N | G71: N | H71: N | I71: N | J71: N | K71: N
A72: Boston Celtics | B72: N | C72: N | D72: N | E72: N | F72: N | G72: N | H72: N | I72: N | J72: N | K72: N
A73: Brooklyn Nets | B73: N | C73: N | D73: N | E73: N | F73: N | G73: N | H73: N | I73: N | J73: N | K73: N
A74: Charlotte Hornets | B74: N | C74: N | D74: N | E74: N | F74: N | G74: N | H74: N | I74: N | J74: N | K74: N
A75: Chicago Bulls | B75: Y | C75: Y | D75: Y | E75: Y | F75: Y | G75: Y | H75: Y | I75: Y | J75: Y | K75: Y
A76: Cleveland Cavaliers | B76: N | C76: N | D76: N | E76: N | F76: N | G76: N | H76: N | I76: N | J76: N | K76: N
A77: Dallas Mavericks | B77: N | C77: N | D77: N | E77: N | F77: N | G77: N | H77: N | I77: N | J77: N | K77: N
A78: Denver Nuggets | B78: Y | C78: Y | D78: Y | E78: Y | F78: Y | G78: Y | H78: Y | I78: Y | J78: Y | K78: Y
A79: Detroit Pistons | B79: Y | C79: Y | D79: N | E79: N | F79: N | G79: N | H79: N | I79: N | J79: N | K79: N
A80: Golden State Warriors | B80: N | C80: N | D80: N | E80: N | F80: Y | G80: Y | H80: Y | I80: Y | J80: Y | K80: Y
...

Sheet Sportico & CNBC
A1: Other Valuation Estimates – 2025–26 Season ($ millions)
A2: Sportico list published Oct 2025; CNBC list published Feb 2026. Forbes column links to the main sheet for comparison. n/a = not found. Hover over a value to see its source.
A3: NBA Team | B3: Forbes | C3: Sportico | D3: CNBC
A4: Atlanta Hawks | B4: ='NBA Valuations'!K5 -> 5000 | C4: 5020 | D4: 5400
A5: Boston Celtics | B5: ='NBA Valuations'!K6 -> 6700 | C5: 6350 | D5: 6300
A6: Brooklyn Nets | B6: ='NBA Valuations'!K7 -> 5600 | C6: 6220 | D6: 6000
A7: Charlotte Hornets | B7: ='NBA Valuations'!K8 -> 3800 | C7: 4130 | D7: 3900
A8: Chicago Bulls | B8: ='NBA Valuations'!K9 -> 6000 | C8: 6120 | D8: 6450
A9: Cleveland Cavaliers | B9: ='NBA Valuations'!K10 -> 4800 | C9: 4860 | D9: n/a
A10: Dallas Mavericks | B10: ='NBA Valuations'!K11 -> 5100 | C10: 5240 | D10: n/a
A11: Denver Nuggets | B11: ='NBA Valuations'!K12 -> 4600 | C11: 4800 | D11: n/a
A12: Detroit Pistons | B12: ='NBA Valuations'!K13 -> 3650 | C12: 4170 | D12: 4000
A13: Golden State Warriors | B13: ='NBA Valuations'!K14 -> 11000 | C13: 11330 | D13: 10800
A14: Houston Rockets | B14: ='NBA Valuations'!K15 -> 5900 | C14: 5530 | D14: 6350
A15: Indiana Pacers | B15: ='NBA Valuations'!K16 -> 4200 | C15: 4760 | D15: n/a
A16: LA Clippers | B16: ='NBA Valuations'!K17 -> 7500 | C16: 6720 | D16: 6900
A17: Los Angeles Lakers | B17: ='NBA Valuations'!K18 -> 10000 | C17: 10000 | D17: 10000
A18: Memphis Grizzlies | B18: ='NBA Valuations'!K19 -> 3500 | C18: 4000 | D18: 3750
A19: Miami Heat | B19: ='NBA Valuations'!K20 -> 5700 | C19: 6030 | D19: 6050
A20: Milwaukee Bucks | B20: ='NBA Valuations'!K21 -> 4300 | C20: 4540 | D20: n/a
A21: Minnesota Timberwolves | B21: ='NBA Valuations'!K22 -> 3600 | C21: 4240 | D21: 3800
A22: New Orleans Pelicans | B22: ='NBA Valuations'!K23 -> 3550 | C22: 4020 | D22: 3850
A23: New York Knicks | B23: ='NBA Valuations'!K24 -> 9750 | C23: 9850 | D23: 10100
A24: Oklahoma City Thunder | B24: ='NBA Valuations'!K25 -> 4350 | C24: 4340 | D24: n/a
A25: Orlando Magic | B25: ='NBA Valuations'!K26 -> 3900 | C25: 4210 | D25: n/a
A26: Philadelphia 76ers | B26: ='NBA Valuations'!K27 -> 5450 | C26: 5610 | D26: 6100
A27: Phoenix Suns | B27: ='NBA Valuations'!K28 -> 5425 | C27: 5090 | D27: n/a
A28: Portland Trail Blazers | B28: ='NBA Valuations'!K29 -> 4250 | C28: 4250 | D28: n/a
A29: Sacramento Kings | B29: ='NBA Valuations'!K30 -> 4450 | C29: 5000 | D29: n/a
A30: San Antonio Spurs | B30: ='NBA Valuations'!K31 -> 4400 | C30: 4500 | D30: n/a
A31: Toronto Raptors | B31: ='NBA Valuations'!K32 -> 5400 | C31: 5220 | D31: n/a
A32: Utah Jazz | B32: ='NBA Valuations'!K33 -> 4100 | C32: 4270 | D32: n/a
A33: Washington Wizards | B33: ='NBA Valuations'!K34 -> 4700 | C33: 4780 | D33: n/a

Sheet Salary Cap
A1: NBA Salary Cap & Team Payrolls
A2: Year = NBA season (2026 = 2025–26). Light yellow = payroll over the salary cap. Bright yellow = over the luxury tax line (team paid a tax penalty). n/a = not found. Hover over values for sources.
A4: League Limits | B4: 2017 | C4: 2018 | D4: 2019 | E4: 2020 | F4: 2021 | G4: 2022 | H4: 2023 | I4: 2024 | J4: 2025 | K4: 2026
A5: Salary Cap | B5: 94143000 | C5: 99093000 | D5: 101869000 | E5: 109140000 | F5: 109140000 | G5: 112414000 | H5: 123655000 | I5: 136021000 | J5: 140588000 | K5: 154647000
A6: Luxury Tax Line | B6: 113287000 | C6: 119266000 | D6: 123733000 | E6: 132627000 | F6: 132627000 | G6: 136606000 | H6: 150267000 | I6: 165294000 | J6: 170814000 | K6: 187895000
A8: Team Payroll (end-of-season tax payroll) | N8: Did Paying the Tax Raise Team Value? (2017 → 2026)
A9: NBA Team | B9: 2017 | C9: 2018 | D9: 2019 | E9: 2020 | F9: 2021 | G9: 2022 | H9: 2023 | I9: 2024 | J9: 2025 | K9: 2026 | N9: NBA Team | O9: Seasons Over Tax | P9: Total Tax Paid | Q9: Value 2017 ($M) | R9: Value 2026 ($M) | S9: Value Growth
A10: Atlanta Hawks | B10: 95576245 | C10: 100108457 | D10: 103686836 | E10: 112298633 | F10: 116695055 | G10: 132777480 | H10: 148576597 | I10: 156139798 | J10: 168381400 | K10: 186769942 | N10: =A10 -> Atlanta Hawks | O10: =COUNTIF(B109:K109,">0")+COUNTIF(B109:K109,"Paid*") -> 0 | P10: =SUM(B109:K109) -> 0 | Q10: ='NBA Valuations'!B5 -> 885 | R10: ='NBA Valuations'!K5 -> 5000 | S10: =R10/Q10-1 -> 4.6497175
A11: Boston Celtics | B11: 93035161 | C11: 115731460 | D11: 126313549 | E11: 118437085 | F11: 130723102 | G11: 135726703 | H11: 176732455 | I11: 183476284 | J11: 193098445 | K11: 187257831 | N11: =A11 -> Boston Celtics | O11: =COUNTIF(B110:K110,">0")+COUNTIF(B110:K110,"Paid*") -> 4 | P11: =SUM(B110:K110) -> 165529276 | Q11: ='NBA Valuations'!B6 -> 2200 | R11: ='NBA Valuations'!K6 -> 6700 | S11: =R11/Q11-1 -> 2.0454545
A12: Brooklyn Nets | B12: 83753138 | C12: 96123331 | D12: 117647794 | E12: 102674920 | F12: 166175317 | G12: 169286329 | H12: 158370057 | I12: 151721032 | J12: 170497768 | K12: 150488034 | N12: =A12 -> Brooklyn Nets | O12: =COUNTIF(B111:K111,">0")+COUNTIF(B111:K111,"Paid*") -> 3 | P12: =SUM(B111:K111) -> 172241611 | Q12: ='NBA Valuations'!B7 -> 1800 | R12: ='NBA Valuations'!K7 -> 5600 | S12: =R12/Q12-1 -> 2.1111111
A13: Charlotte Hornets | B13: 102068166 | C13: 117228164 | D13: 121810182 | E13: 124096301 | F13: 107134070 | G13: 120990744 | H13: 124552439 | I13: 137159325 | J13: 167307747 | K13: 183430210 | N13: =A13 -> Charlotte Hornets | O13: =COUNTIF(B112:K112,">0")+COUNTIF(B112:K112,"Paid*") -> 0 | P13: =SUM(B112:K112) -> 0 | Q13: ='NBA Valuations'!B8 -> 780 | R13: ='NBA Valuations'!K8 -> 3800 | S13: =R13/Q13-1 -> 3.8717949
A14: Chicago Bulls | B14: 93281333 | C14: 90105625 | D14: 112026072 | E14: 113208742 | F14: 128065350 | G14: 134629608 | H14: 149464753 | I14: 164432853 | J14: 165919354 | K14: 182833631 | N14: =A14 -> Chicago Bulls | O14: =COUNTIF(B113:K113,">0")+COUNTIF(B113:K113,"Paid*") -> 0 | P14: =SUM(B113:K113) -> 0 | Q14: ='NBA Valuations'!B9 -> 2500 | R14: ='NBA Valuations'!K9 -> 6000 | S14: =R14/Q14-1 -> 1.4
A15: Cleveland Cavaliers | B15: 126590785 | C15: 135980450 | D15: 123697967 | E15: 132181946 | F15: 126734856 | G15: 133138401 | H15: 149251300 | I15: 163939463 | J15: 170144576 | K15: 212345289 | N15: =A15 -> Cleveland Cavaliers | O15: =COUNTIF(B114:K114,">0")+COUNTIF(B114:K114,"Paid*") -> 3 | P15: =SUM(B114:K114) -> 144145470 | Q15: ='NBA Valuations'!B10 -> 1200 | R15: ='NBA Valuations'!K10 -> 4800 | S15: =R15/Q15-1 -> 3
A16: Dallas Mavericks | B16: 105673612 | C16: 85464575 | D16: 88434197 | E16: 121299167 | F16: 125815404 | G16: 124750009 | H16: 173385738 | I16: 164631111 | J16: 174243724 | K16: 183036411 | N16: =A16 -> Dallas Mavericks | O16: =COUNTIF(B115:K115,">0")+COUNTIF(B115:K115,"Paid*") -> 2 | P16: =SUM(B115:K115) -> 61839854 | Q16: ='NBA Valuations'!B11 -> 1500 | R16: ='NBA Valuations'!K11 -> 5100 | S16: =R16/Q16-1 -> 2.4
A17: Denver Nuggets | B17: 82581936 | C17: 106515203 | D17: 116799912 | E17: 130263965 | F17: 128579406 | G17: 136054862 | H17: 160688004 | I17: 176890198 | J17: 182574315 | K17: 187289504 | N17: =A17 -> Denver Nuggets | O17: =COUNTIF(B116:K116,">0")+COUNTIF(B116:K116,"Paid*") -> 3 | P17: =SUM(B116:K116) -> 57899793 | Q17: ='NBA Valuations'!B12 -> 890 | R17: ='NBA Valuations'!K12 -> 4600 | S17: =R17/Q17-1 -> 4.1685393
A18: Detroit Pistons | B18: 107901937 | C18: 118897722 | D18: 123481463 | E18: 131251409 | F18: 115085331 | G18: 129753205 | H18: 127664973 | I18: 135124059 | J18: 141631285 | K18: 185741609 | N18: =A18 -> Detroit Pistons | O18: =COUNTIF(B117:K117,">0")+COUNTIF(B117:K117,"Paid*") -> 0 | P18: =SUM(B117:K117) -> 0 | Q18: ='NBA Valuations'!B13 -> 900 | R18: ='NBA Valuations'!K13 -> 3650 | S18: =R18/Q18-1 -> 3.0555556
A19: Golden State Warriors | B19: 100255533 | C19: 136027513 | D19: 145463097 | E19: 132317044 | F19: 169212512 | G19: 175858992 | H19: 188371492 | I19: 205572662 | J19: 176887433 | K19: 204744987 | N19: =A19 -> Golden State Warriors | O19: =COUNTIF(B118:K118,">0")+COUNTIF(B118:K118,"Paid*") -> 8 | P19: =SUM(B118:K118) -> 744152564 | Q19: ='NBA Valuations'!B14 -> 2600 | R19: ='NBA Valuations'!K14 -> 11000 | S19: =R19/Q19-1 -> 3.2307692
A20: Houston Rockets | B20: 91492845 | C20: 118271451 | D20: 121818799 | E20: 127339416 | F20: 128530270 | G20: 130727899 | H20: 135916481 | I20: 145269849 | J20: 169193565 | K20: 194689411 | N20: =A20 -> Houston Rockets | O20: =COUNTIF(B119:K119,">0")+COUNTIF(B119:K119,"Paid*") -> 1 | P20: =SUM(B119:K119) -> 7071764 | Q20: ='NBA Valuations'!B15 -> 1700 | R20: ='NBA Valuations'!K15 -> 5900 | S20: =R20/Q20-1 -> 2.4705882
A21: Indiana Pacers | B21: 94002004 | C21: 93661969 | D21: 110579462 | E21: 114591944 | F21: 128919308 | G21: 136538630 | H21: 122361469 | I21: 144877509 | J21: 169319284 | K21: 187759899 | N21: =A21 -> Indiana Pacers | O21: =COUNTIF(B120:K120,">0")+COUNTIF(B120:K120,"Paid*") -> 0 | P21: =SUM(B120:K120) -> 0 | Q21: ='NBA Valuations'!B16 -> 880 | R21: ='NBA Valuations'!K16 -> 4200 | S21: =R21/Q21-1 -> 3.7727273
... A39: Washington Wizards | B39: 103211636 | C39: 124114043 | D39: 123613751 | E39: 97584993 | F39: 130577328 | G39: 126147247 | H39: 150166106 | I39: 147595496 | J39: 169656752 | K39: 187070382 | N39: =A39 -> Washington Wizards | O39: =COUNTIF(B138:K138,">0")+COUNTIF(B138:K138,"Paid*") -> 1 | P39: =SUM(B138:K138) -> 7000000 | Q39: ='NBA Valuations'!B34 -> 1000 | R39: ='NBA Valuations'!K34 -> 4700 | S39: =R39/Q39-1 -> 3.7
A41: Amount Over the Salary Cap | N41: Summary
A42: NBA Team | B42: 2017 | C42: 2018 | D42: 2019 | E42: 2020 | F42: 2021 | G42: 2022 | H42: 2023 | I42: 2024 | J42: 2025 | K42: 2026 | N42: ="Avg value growth – "&COUNTIF(O10:O39,">0")&" teams that paid the tax" -> Avg value growth – 20 teams that paid the tax | S42: =AVERAGEIF(O10:O39,">0",S10:S39) -> 3.2380671
A43: =A10 -> Atlanta Hawks | B43: =IF(ISNUMBER(B10),MAX(0,B10-B$5),"n/a") -> 1433245 | C43: =IF(ISNUMBER(C10),MAX(0,C10-C$5),"n/a") -> 1015457 | D43: =IF(ISNUMBER(D10),MAX(0,D10-D$5),"n/a") -> 1817836 | E43: =IF(ISNUMBER(E10),MAX(0,E10-E$5),"n/a") -> 3158633 | F43: =IF(ISNUMBER(F10),MAX(0,F10-F$5),"n/a") -> 7555055 | G43: =IF(ISNUMBER(G10),MAX(0,G10-G$5),"n/a") -> 20363480 | H43: =IF(ISNUMBER(H10),MAX(0,H10-H$5),"n/a") -> 24921597 | I43: =IF(ISNUMBER(I10),MAX(0,I10-I$5),"n/a") -> 20118798 | ... K43: =IF(ISNUMBER(K10),MAX(0,K10-K$5),"n/a") -> 32122942 | N43: ="Avg value growth – "&COUNTIF(O10:O39,0)&" teams that never paid" -> Avg value growth – 10 teams that never paid | S43: =AVERAGEIF(O10:O39,0,S10:S39) -> 3.286476
A44: =A11 -> Boston Celtics | B44: =IF(ISNUMBER(B11),MAX(0,B11-B$5),"n/a") -> 0 | C44: =IF(ISNUMBER(C11),MAX(0,C11-C$5),"n/a") -> 16638460 | D44: =IF(ISNUMBER(D11),MAX(0,D11-D$5),"n/a") -> 24444549 | E44: =IF(ISNUMBER(E11),MAX(0,E11-E$5),"n/a") -> 9297085 | F44: =IF(ISNUMBER(F11),MAX(0,F11-F$5),"n/a") -> 21583102 | G44: =IF(ISNUMBER(G11),MAX(0,G11-G$5),"n/a") -> 23312703 | H44: =IF(ISNUMBER(H11),MAX(0,H11-H$5),"n/a") -> 53077455 | I44: =IF(ISNUMBER(I11),MAX(0,I11-I$5),"n/a") -> 47455284 | ... K44: =IF(ISNUMBER(K11),MAX(0,K11-K$5),"n/a") -> 32610831
A45: =A12 -> Brooklyn Nets | B45: =IF(ISNUMBER(B12),MAX(0,B12-B$5),"n/a") -> 0 | C45: =IF(ISNUMBER(C12),MAX(0,C12-C$5),"n/a") -> 0 | D45: =IF(ISNUMBER(D12),MAX(0,D12-D$5),"n/a") -> 15778794 | E45: =IF(ISNUMBER(E12),MAX(0,E12-E$5),"n/a") -> 0 | F45: =IF(ISNUMBER(F12),MAX(0,F12-F$5),"n/a") -> 57035317 | G45: =IF(ISNUMBER(G12),MAX(0,G12-G$5),"n/a") -> 56872329 | H45: =IF(ISNUMBER(H12),MAX(0,H12-H$5),"n/a") -> 34715057 | I45: =IF(ISNUMBER(I12),MAX(0,I12-I$5),"n/a") -> 15700032 | ... K45: =IF(ISNUMBER(K12),MAX(0,K12-K$5),"n/a") -> 0 | N45: What This Chart Shows
A46: =A13 -> Charlotte Hornets | B46: =IF(ISNUMBER(B13),MAX(0,B13-B$5),"n/a") -> 7925166 | C46: =IF(ISNUMBER(C13),MAX(0,C13-C$5),"n/a") -> 18135164 | D46: =IF(ISNUMBER(D13),MAX(0,D13-D$5),"n/a") -> 19941182 | E46: =IF(ISNUMBER(E13),MAX(0,E13-E$5),"n/a") -> 14956301 | F46: =IF(ISNUMBER(F13),MAX(0,F13-F$5),"n/a") -> 0 | G46: =IF(ISNUMBER(G13),MAX(0,G13-G$5),"n/a") -> 8576744 | H46: =IF(ISNUMBER(H13),MAX(0,H13-H$5),"n/a") -> 897439 | I46: =IF(ISNUMBER(I13),MAX(0,I13-I$5),"n/a") -> 1138325 | ... K46: =IF(ISNUMBER(K13),MAX(0,K13-K$5),"n/a") -> 28783210 | N46: How to read it: The salary cap and luxury tax line (rows 5–6) are the same for every team each season. The cap is a 'soft' cap – teams can legally go over it to keep their own players, so most teams sit above it (light yellow). The luxury tax line is the real spending limit: any team over it at the end of the regular season pays a penalty (bright yellow).
A47: =A14 -> Chicago Bulls | B47: =IF(ISNUMBER(B14),MAX(0,B14-B$5),"n/a") -> 0 | C47: =IF(ISNUMBER(C14),MAX(0,C14-C$5),"n/a") -> 0 | D47: =IF(ISNUMBER(D14),MAX(0,D14-D$5),"n/a") -> 10157072 | E47: =IF(ISNUMBER(E14),MAX(0,E14-E$5),"n/a") -> 4068742 | F47: =IF(ISNUMBER(F14),MAX(0,F14-F$5),"n/a") -> 18925350 | G47: =IF(ISNUMBER(G14),MAX(0,G14-G$5),"n/a") -> 22215608 | H47: =IF(ISNUMBER(H14),MAX(0,H14-H$5),"n/a") -> 25809753 | I47: =IF(ISNUMBER(I14),MAX(0,I14-I$5),"n/a") -> 28411853 | ... K47: =IF(ISNUMBER(K14),MAX(0,K14-K$5),"n/a") -> 28186631 | N47: Who went over: 20 of 30 teams paid the tax at least once from 2016–17 to 2025–26. The Golden State Warriors were the biggest spenders by far – 8 tax seasons and about $744M in penalties, including a record $170M in 2021–22 (a championship year). The LA Clippers (6 seasons, ~$381M), Phoenix Suns (~$274M), Milwaukee Bucks (~$219M), Brooklyn Nets (~$172M), Los Angeles Lakers (~$168M) and Boston Celtics (~$166M) follow. Ten teams never paid, including the Hawks, Pacers, Spurs and Grizzlies.
A48: =A15 -> Cleveland Cavaliers | B48: =IF(ISNUMBER(B15),MAX(0,B15-B$5),"n/a") -> 32447785 | C48: =IF(ISNUMBER(C15),MAX(0,C15-C$5),"n/a") -> 36887450 | D48: =IF(ISNUMBER(D15),MAX(0,D15-D$5),"n/a") -> 21828967 | E48: =IF(ISNUMBER(E15),MAX(0,E15-E$5),"n/a") -> 23041946 | F48: =IF(ISNUMBER(F15),MAX(0,F15-F$5),"n/a") -> 17594856 | G48: =IF(ISNUMBER(G15),MAX(0,G15-G$5),"n/a") -> 20724401 | H48: =IF(ISNUMBER(H15),MAX(0,H15-H$5),"n/a") -> 25596300 | I48: =IF(ISNUMBER(I15),MAX(0,I15-I$5),"n/a") -> 27918463 | ... K48: =IF(ISNUMBER(K15),MAX(0,K15-K$5),"n/a") -> 57698289 | N48: Trend: Only 2–5 teams paid the tax each season until 2020–21. Starting in 2021–22, 7–10 teams paid every year, and bills jumped into the hundreds of millions. The 2023 labor deal added stricter 'apron' penalties, and by 2025–26 several big spenders (Celtics, Suns, Bucks) had cut payroll to get under the line.
A49: =A16 -> Dallas Mavericks | B49: =IF(ISNUMBER(B16),MAX(0,B16-B$5),"n/a") -> 11530612 | C49: =IF(ISNUMBER(C16),MAX(0,C16-C$5),"n/a") -> 0 | D49: =IF(ISNUMBER(D16),MAX(0,D16-D$5),"n/a") -> 0 | E49: =IF(ISNUMBER(E16),MAX(0,E16-E$5),"n/a") -> 12159167 | F49: =IF(ISNUMBER(F16),MAX(0,F16-F$5),"n/a") -> 16675404 | G49: =IF(ISNUMBER(G16),MAX(0,G16-G$5),"n/a") -> 12336009 | H49: =IF(ISNUMBER(H16),MAX(0,H16-H$5),"n/a") -> 49730738 | I49: =IF(ISNUMBER(I16),MAX(0,I16-I$5),"n/a") -> 28610111 | ... K49: =IF(ISNUMBER(K16),MAX(0,K16-K$5),"n/a") -> 28389411 | N49: What happened to valuation: Spending over the tax did not make teams grow faster in value. Teams that paid the tax grew about the same (≈324% on average) as teams that never paid (≈329%) – see the summary above. The Warriors spent the most and became the most valuable team, but their value growth (+323%) was close to average. The 76ers grew the most (+581%) while paying only modest tax, and the never-taxpaying Hawks grew +465%. Big spenders tend to be big-market teams that were already valuable; market size, arenas and league-wide TV money drove value more than payroll did. Caution: taxpaying teams are mostly big-market teams with high starting values, and in percentage terms those teams grew more slowly over this period anyway, so this comparison is confounded and does not show cause. The Oct 2023 Forbes list compressed values (small teams caught up), which affects every growth comparison.
A50: =A17 -> Denver Nuggets | B50: =IF(ISNUMBER(B17),MAX(0,B17-B$5),"n/a") -> 0 | C50: =IF(ISNUMBER(C17),MAX(0,C17-C$5),"n/a") -> 7422203 | D50: =IF(ISNUMBER(D17),MAX(0,D17-D$5),"n/a") -> 14930912 | E50: =IF(ISNUMBER(E17),MAX(0,E17-E$5),"n/a") -> 21123965 | F50: =IF(ISNUMBER(F17),MAX(0,F17-F$5),"n/a") -> 19439406 | G50: =IF(ISNUMBER(G17),MAX(0,G17-G$5),"n/a") -> 23640862 | H50: =IF(ISNUMBER(H17),MAX(0,H17-H$5),"n/a") -> 37033004 | I50: =IF(ISNUMBER(I17),MAX(0,I17-I$5),"n/a") -> 40869198 | ... K50: =IF(ISNUMBER(K17),MAX(0,K17-K$5),"n/a") -> 32642504 | N50: Data notes: Payrolls for 2017–2022 (seasons 2016–17 to 2021–22) are from Spotrac's tax tracker (user screenshots); 2023–2026 are from Sports Business Classroom. Both are end-of-season tax payroll, but the two sources may differ slightly. A 2015–16 payroll/tax block (A141:C172) feeds only the Panel's 2017 rows; its tax bills are Spotrac estimates. Utah's 2020–21 tax bill (F137, yellow) is a Spotrac estimate. The 2027 columns were removed. Some early bills are rounded estimates; see cell notes.
A51: =A18 -> Detroit Pistons | B51: =IF(ISNUMBER(B18),MAX(0,B18-B$5),"n/a") -> 13758937 | C51: =IF(ISNUMBER(C18),MAX(0,C18-C$5),"n/a") -> 19804722 | D51: =IF(ISNUMBER(D18),MAX(0,D18-D$5),"n/a") -> 21612463 | E51: =IF(ISNUMBER(E18),MAX(0,E18-E$5),"n/a") -> 22111409 | F51: =IF(ISNUMBER(F18),MAX(0,F18-F$5),"n/a") -> 5945331 | G51: =IF(ISNUMBER(G18),MAX(0,G18-G$5),"n/a") -> 17339205 | H51: =IF(ISNUMBER(H18),MAX(0,H18-H$5),"n/a") -> 4009973 | I51: =IF(ISNUMBER(I18),MAX(0,I18-I$5),"n/a") -> 0 | ... K51: =IF(ISNUMBER(K18),MAX(0,K18-K$5),"n/a") -> 31094609
A52: =A19 -> Golden State Warriors | B52: =IF(ISNUMBER(B19),MAX(0,B19-B$5),"n/a") -> 6112533 | C52: =IF(ISNUMBER(C19),MAX(0,C19-C$5),"n/a") -> 36934513 | D52: =IF(ISNUMBER(D19),MAX(0,D19-D$5),"n/a") -> 43594097 | E52: =IF(ISNUMBER(E19),MAX(0,E19-E$5),"n/a") -> 23177044 | F52: =IF(ISNUMBER(F19),MAX(0,F19-F$5),"n/a") -> 60072512 | G52: =IF(ISNUMBER(G19),MAX(0,G19-G$5),"n/a") -> 63444992 | H52: =IF(ISNUMBER(H19),MAX(0,H19-H$5),"n/a") -> 64716492 | I52: =IF(ISNUMBER(I19),MAX(0,I19-I$5),"n/a") -> 69551662 | ... K52: =IF(ISNUMBER(K19),MAX(0,K19-K$5),"n/a") -> 50097987
A53: =A20 -> Houston Rockets | B53: =IF(ISNUMBER(B20),MAX(0,B20-B$5),"n/a") -> 0 | C53: =IF(ISNUMBER(C20),MAX(0,C20-C$5),"n/a") -> 19178451 | D53: =IF(ISNUMBER(D20),MAX(0,D20-D$5),"n/a") -> 19949799 | E53: =IF(ISNUMBER(E20),MAX(0,E20-E$5),"n/a") -> 18199416 | F53: =IF(ISNUMBER(F20),MAX(0,F20-F$5),"n/a") -> 19390270 | G53: =IF(ISNUMBER(G20),MAX(0,G20-G$5),"n/a") -> 18313899 | H53: =IF(ISNUMBER(H20),MAX(0,H20-H$5),"n/a") -> 12261481 | I53: =IF(ISNUMBER(I20),MAX(0,I20-I$5),"n/a") -> 9248849 | ... K53: =IF(ISNUMBER(K20),MAX(0,K20-K$5),"n/a") -> 40042411
A54: =A21 -> Indiana Pacers | B54: =IF(ISNUMBER(B21),MAX(0,B21-B$5),"n/a") -> 0 | C54: =IF(ISNUMBER(C21),MAX(0,C21-C$5),"n/a") -> 0 | D54: =IF(ISNUMBER(D21),MAX(0,D21-D$5),"n/a") -> 8710462 | E54: =IF(ISNUMBER(E21),MAX(0,E21-E$5),"n/a") -> 5451944 | F54: =IF(ISNUMBER(F21),MAX(0,F21-F$5),"n/a") -> 19779308 | G54: =IF(ISNUMBER(G21),MAX(0,G21-G$5),"n/a") -> 24124630 | H54: =IF(ISNUMBER(H21),MAX(0,H21-H$5),"n/a") -> 0 | I54: =IF(ISNUMBER(I21),MAX(0,I21-I$5),"n/a") -> 8856509 | ... K54: =IF(ISNUMBER(K21),MAX(0,K21-K$5),"n/a") -> 33112899
A55: =A22 -> LA Clippers | B55: =IF(ISNUMBER(B22),MAX(0,B22-B$5),"n/a") -> 21364492 | C55: =IF(ISNUMBER(C22),MAX(0,C22-C$5),"n/a") -> 19724049 | D55: =IF(ISNUMBER(D22),MAX(0,D22-D$5),"n/a") -> 16777874 | E55: =IF(ISNUMBER(E22),MAX(0,E22-E$5),"n/a") -> 21014932 | F55: =IF(ISNUMBER(F22),MAX(0,F22-F$5),"n/a") -> 28314771 | G55: =IF(ISNUMBER(G22),MAX(0,G22-G$5),"n/a") -> 53748398 | H55: =IF(ISNUMBER(H22),MAX(0,H22-H$5),"n/a") -> 67534228 | I55: =IF(ISNUMBER(I22),MAX(0,I22-I$5),"n/a") -> 64039815 | ... K55: =IF(ISNUMBER(K22),MAX(0,K22-K$5),"n/a") -> 35469914
A56: =A23 -> Los Angeles Lakers | B56: =IF(ISNUMBER(B23),MAX(0,B23-B$5),"n/a") -> 61120 | C56: =IF(ISNUMBER(C23),MAX(0,C23-C$5),"n/a") -> 3084393 | D56: =IF(ISNUMBER(D23),MAX(0,D23-D$5),"n/a") -> 3310629 | E56: =IF(ISNUMBER(E23),MAX(0,E23-E$5),"n/a") -> 8816507 | F56: =IF(ISNUMBER(F23),MAX(0,F23-F$5),"n/a") -> 27773272 | G56: =IF(ISNUMBER(G23),MAX(0,G23-G$5),"n/a") -> 44222217 | H56: =IF(ISNUMBER(H23),MAX(0,H23-H$5),"n/a") -> 43822836 | I56: =IF(ISNUMBER(I23),MAX(0,I23-I$5),"n/a") -> 32034984 | ... K56: =IF(ISNUMBER(K23),MAX(0,K23-K$5),"n/a") -> 40655470
A57: =A24 -> Memphis Grizzlies | B57: =IF(ISNUMBER(B24),MAX(0,B24-B$5),"n/a") -> 16726863 | C57: =IF(ISNUMBER(C24),MAX(0,C24-C$5),"n/a") -> 10809725 | D57: =IF(ISNUMBER(D24),MAX(0,D24-D$5),"n/a") -> 20207384 | E57: =IF(ISNUMBER(E24),MAX(0,E24-E$5),"n/a") -> 20658650 | F57: =IF(ISNUMBER(F24),MAX(0,F24-F$5),"n/a") -> 21864198 | G57: =IF(ISNUMBER(G24),MAX(0,G24-G$5),"n/a") -> 3580102 | H57: =IF(ISNUMBER(H24),MAX(0,H24-H$5),"n/a") -> 2011556 | I57: =IF(ISNUMBER(I24),MAX(0,I24-I$5),"n/a") -> 21874653 | ... K57: =IF(ISNUMBER(K24),MAX(0,K24-K$5),"n/a") -> 2319505
A58: =A25 -> Miami Heat | B58: =IF(ISNUMBER(B25),MAX(0,B25-B$5),"n/a") -> 7703108 | C58: =IF(ISNUMBER(C25),MAX(0,C25-C$5),"n/a") -> 5972917 | D58: =IF(ISNUMBER(D25),MAX(0,D25-D$5),"n/a") -> 21309641 | E58: =IF(ISNUMBER(E25),MAX(0,E25-E$5),"n/a") -> 25475772 | F58: =IF(ISNUMBER(F25),MAX(0,F25-F$5),"n/a") -> 23206118 | G58: =IF(ISNUMBER(G25),MAX(0,G25-G$5),"n/a") -> 23108461 | H58: =IF(ISNUMBER(H25),MAX(0,H25-H$5),"n/a") -> 25455825 | I58: =IF(ISNUMBER(I25),MAX(0,I25-I$5),"n/a") -> 38948385 | ... K58: =IF(ISNUMBER(K25),MAX(0,K25-K$5),"n/a") -> 32354274
A59: =A26 -> Milwaukee Bucks | B59: =IF(ISNUMBER(B26),MAX(0,B26-B$5),"n/a") -> 0 | C59: =IF(ISNUMBER(C26),MAX(0,C26-C$5),"n/a") -> 17121360 | D59: =IF(ISNUMBER(D26),MAX(0,D26-D$5),"n/a") -> 20499320 | E59: =IF(ISNUMBER(E26),MAX(0,E26-E$5),"n/a") -> 21264531 | F59: =IF(ISNUMBER(F26),MAX(0,F26-F$5),"n/a") -> 24104133 | G59: =IF(ISNUMBER(G26),MAX(0,G26-G$5),"n/a") -> 46571385 | H59: =IF(ISNUMBER(H26),MAX(0,H26-H$5),"n/a") -> 56351727 | I59: =IF(ISNUMBER(I26),MAX(0,I26-I$5),"n/a") -> 46323527 | ... K59: =IF(ISNUMBER(K26),MAX(0,K26-K$5),"n/a") -> 26950778
A60: =A27 -> Minnesota Timberwolves | B60: =IF(ISNUMBER(B27),MAX(0,B27-B$5),"n/a") -> 0 | C60: =IF(ISNUMBER(C27),MAX(0,C27-C$5),"n/a") -> 6245698 | D60: =IF(ISNUMBER(D27),MAX(0,D27-D$5),"n/a") -> 18562914 | E60: =IF(ISNUMBER(E27),MAX(0,E27-E$5),"n/a") -> 24403271 | F60: =IF(ISNUMBER(F27),MAX(0,F27-F$5),"n/a") -> 19884393 | G60: =IF(ISNUMBER(G27),MAX(0,G27-G$5),"n/a") -> 23691827 | H60: =IF(ISNUMBER(H27),MAX(0,H27-H$5),"n/a") -> 19639647 | I60: =IF(ISNUMBER(I27),MAX(0,I27-I$5),"n/a") -> 28507789 | ... K60: =IF(ISNUMBER(K27),MAX(0,K27-K$5),"n/a") -> 39174377
...

Sheet Team Performance
A1: NBA Team Performance vs. Franchise Value (2016-17 to 2025-26)
A2: Regular-season records and playoff results by season. Gold = champion; red shading = one of the 5 worst records that season. Value growth links to the NBA Valuations tab (next Forbes list ÷ prior list).
A4: Wins
A5: NBA Team | B5: 2016-17 | C5: 2017-18 | D5: 2018-19 | E5: 2019-20 | F5: 2020-21 | G5: 2021-22 | H5: 2022-23 | I5: 2023-24 | J5: 2024-25 | K5: 2025-26
A6: Atlanta Hawks | B6: 43 | C6: 24 | D6: 29 | E6: 20 | F6: 41 | G6: 43 | H6: 41 | I6: 36 | J6: 40 | K6: 46 | M6: Playoff Score Key
A7: Boston Celtics | B7: 53 | C7: 55 | D7: 49 | E7: 48 | F7: 36 | G7: 51 | H7: 57 | I7: 64 | J7: 61 | K7: 56 | M7: Playoff Result | N7: Score
A8: Brooklyn Nets | B8: 20 | C8: 28 | D8: 42 | E8: 35 | F8: 48 | G8: 44 | H8: 45 | I8: 32 | J8: 26 | K8: 20 | M8: Missed Playoffs | N8: 0
A9: Charlotte Hornets | B9: 36 | C9: 36 | D9: 39 | E9: 23 | F9: 33 | G9: 43 | H9: 27 | I9: 21 | J9: 19 | K9: 44 | M9: Lost First Round | N9: 1
A10: Chicago Bulls | B10: 41 | C10: 27 | D10: 22 | E10: 22 | F10: 31 | G10: 46 | H10: 40 | I10: 39 | J10: 39 | K10: 31 | M10: Lost Conf Semi | N10: 2
A11: Cleveland Cavaliers | B11: 51 | C11: 50 | D11: 19 | E11: 19 | F11: 22 | G11: 44 | H11: 51 | I11: 48 | J11: 64 | K11: 52 | M11: Lost Conf Finals | N11: 3
A12: Dallas Mavericks | B12: 33 | C12: 24 | D12: 33 | E12: 43 | F12: 42 | G12: 52 | H12: 38 | I12: 50 | J12: 39 | K12: 26 | M12: Lost Finals | N12: 4
A13: Denver Nuggets | B13: 40 | C13: 46 | D13: 54 | E13: 46 | F13: 47 | G13: 48 | H13: 53 | I13: 57 | J13: 50 | K13: 54 | M13: Won Finals | N13: 5
A14: Detroit Pistons | B14: 37 | C14: 39 | D14: 41 | E14: 20 | F14: 20 | G14: 23 | H14: 17 | I14: 14 | J14: 44 | K14: 60
A15: Golden State Warriors | B15: 67 | C15: 58 | D15: 57 | E15: 15 | F15: 39 | G15: 53 | H15: 44 | I15: 46 | J15: 48 | K15: 37 | M15: Does Winning Raise Franchise Value? (2016-17 to 2024-25 seasons)
A16: Houston Rockets | B16: 55 | C16: 65 | D16: 53 | E16: 44 | F16: 17 | G16: 20 | H16: 22 | I16: 41 | J16: 52 | K16: 52 | M16: Measure | N16: Result
A17: Indiana Pacers | B17: 42 | C17: 48 | D17: 48 | E17: 45 | F17: 34 | G17: 25 | H17: 35 | I17: 47 | J17: 50 | K17: 19 | M17: Correlation: win % vs value growth (vs league) | N17: =CORREL(B72:J101,B207:J236) -> 0.058014323
A18: LA Clippers | B18: 51 | C18: 42 | D18: 48 | E18: 49 | F18: 47 | G18: 42 | H18: 44 | I18: 51 | J18: 50 | K18: 42 | M18: Correlation: playoff score vs value growth (vs league) | N18: =CORREL(B140:J169,B207:J236) -> 0.025596013
A19: Los Angeles Lakers | B19: 26 | C19: 35 | D19: 37 | E19: 52 | F19: 42 | G19: 33 | H19: 43 | I19: 47 | J19: 50 | K19: 53 | M19: Team-seasons where franchise value fell | N19: =COUNTIF(B173:J202,"<0")&" of "&COUNT(B173:J202) -> 3 of 270
A20: Memphis Grizzlies | B20: 43 | C20: 22 | D20: 33 | E20: 34 | F20: 38 | G20: 56 | H20: 51 | I20: 27 | J20: 48 | K20: 25
A21: Miami Heat | B21: 41 | C21: 44 | D21: 39 | E21: 44 | F21: 40 | G21: 53 | H21: 44 | I21: 46 | J21: 37 | K21: 43 | M21: Playoff Result | N21: Team-Seasons | O21: Avg Value Growth | P21: vs League Avg
